Workbook

Sheet INSTRUCCIONES
A1: SIVAR DOGS — GUÍA DE USO DEL SISTEMA
A3: CONVENCIÓN DE COLORES
A4: Azul (texto) | B4: Celda de INPUT — aquí ingresas los datos del día
A5: Negro (texto) | B5: Fórmula automática — no modificar
A6: Verde (texto) | B6: Referencia a otra hoja — no modificar
A8: FLUJO DIARIO DE USO
A9: 1. Abrir CIERRE_DIARIO | B9: Cambiar la fecha en C4
A10: 2. Sección 1 — Inventario | B10: Ingresar: Inicio, Compras, Cortesías, Pérdida, Sobra de cada producto
A11: 3. Sección 2 — Tickets | B11: Ingresar cantidad ticketeada de cada producto
A12: 4. Sección 3 — Ingresos | B12: Ingresar: Corte Efectivo, POS, PeYa, Transferencia, cada Gasto con su descripción
A13: 5. Sección 3 — Caja | B13: Ingresar Vuelto Inicial (heredado de ayer) y Vuelto Final
A14: 6. Revisar KPIs | B14: Los 4 KPIs se calculan automáticamente — revisar semáforo de brecha
A15: 7. Copiar a BASE_DATOS | B15: Copiar los valores calculados a la hoja BASE_DATOS en la siguiente fila disponible
A17: REGLAS CRÍTICAS
A18: Pan = Salchicha | B18: Si difieren es hallazgo crítico — investigar antes de continuar
A19: Lays confirma combos | B19: Si lays en inventario < combos ticketeados, descartar combo sin lays (y su soda)
A20: No ticketeados = Clásicos | B20: Asumir siempre clásico ($1.50) para auditoría. Precio ponderado solo para resumen mensual.
A21: Sobrante también es alerta | B21: Un sobrante recurrente puede indicar autopréstamo. Registrar como Devolución.
A22: Tag [REVISAR] | B22: Si falta un dato, asumir 0 y agregar [REVISAR] en la columna Notas para concilio posterior
A23: Inicio del día | B23: Inicio de inventario = Sobra del día anterior. Vuelto inicial = Vuelto final del día anterior.
A25: SEMÁFORO DE BRECHA
A26: Sobrante $0-$5 | B26: 🟢 Verde — Día sano
A27: Sobrante $5-$10 | B27: 🟡 Amarillo — Monitorear
A28: Sobrante $10-$15 | B28: 🟠 Naranja — Revisar autopréstamo
A29: Sobrante >$15 | B29: 🔴 Rojo — Acción inmediata
A30: Faltante $0-$5 | B30: 🟡 Amarillo — Revisar conteo (faltante siempre más grave)
A31: Faltante $5-$10 | B31: 🟠 Naranja — Investigar causa
A32: Faltante >$10 | B32: 🔴 Rojo — Acción inmediata

Sheet PARAMETROS
A1: SIVAR DOGS — PARÁMETROS DEL SISTEMA
A2: Parque San Martín · Santa Tecla, El Salvador — Hoja de referencia para todas las hojas del sistema
A4: MENÚ Y PRECIOS | E4: EMPAQUES — UNIDADES
A5: Producto | B5: Precio Venta | C5: Tipo | E5: Insumo | F5: Unidades/Envase | G5: Nota
A6: Hotdog Clasico | B6: 1.5 | C6: Individual | E6: Pan Sanfran | F6: 12 | G6: Bolsa — Todos los HD excepto Basico
A7: Hotdog Chilidog | B7: 2 | C7: Individual | E7: Pan Unica | F7: 10 | G7: Bolsa — Solo Hotdog Basico
A8: Hotdog Chickedog | B8: 2 | C8: Individual | E8: Salchicha Jumbo | F8: 16 | G8: Paquete — Todos excepto Basico
A9: Hotdog Basico | B9: 1 | C9: Individual | E9: Salchicha Mini Jumbo | F9: 24 | G9: Paquete — Solo Hotdog Basico
A10: Combo Clasico | B10: 2.75 | C10: Combo
A11: Combo Especialidad | B11: 3.25 | C11: Combo
A12: Soda / Bebida Lata | B12: 1 | C12: Bebida
A13: Lays Individual | B13: 0.5 | C13: Snack
A14: Lays en Combo | B14: 0.25 | C14: Snack
A15: Flanes | B15: 0.65 | C15: Snack
A16: Alitas | B16: 4 | C16: Otro
A17: Chunks | B17: 4 | C17: Otro
A21: RECETAS POR PRODUCTO | E21: SEMÁFORO DE BRECHA
A22: Producto | B22: Pan | C22: Salchicha | E22: Tipo | F22: Rango $ | G22: Estado
A23: Hotdog Clasico | B23: Pan Sanfran | C23: Salchicha Jumbo | E23: Sobrante (+) | F23: $0 — $5 | G23: VERDE
A24: Hotdog Chilidog | B24: Pan Sanfran | C24: Salchicha Jumbo | E24: Sobrante (+) | F24: $5 — $10 | G24: AMARILLO
A25: Hotdog Chickedog | B25: Pan Sanfran | C25: Salchicha Jumbo | E25: Sobrante (+) | F25: $10 — $15 | G25: NARANJA
A26: Hotdog Basico | B26: Pan Unica | C26: Salchicha Mini Jumbo | E26: Sobrante (+) | F26: > $15 | G26: ROJO
A27: Combo Clasico | B27: Pan Sanfran | C27: Salchicha Jumbo | E27: Faltante (-) | F27: $0 — $5 | G27: AMARILLO
A28: Combo Especialidad | B28: Pan Sanfran | C28: Salchicha Jumbo | E28: Faltante (-) | F28: $5 — $10 | G28: NARANJA
E29: Faltante (-) | F29: > $10 | G29: ROJO
A31: CONFIGURACIÓN CAJA BASE
A32: Caja Base Ideal ($) | B32: 45 | C32: Modificar aquí si cambia el fondo
A34: NOTA: | B34: Todas las hojas referencian estos parámetros. No modificar estructura de celdas.

Sheet CIERRE_DIARIO
A1: SIVAR DOGS — CIERRE DIARIO
A2: Parque San Martín · Santa Tecla · Ingrese los datos del corte en las celdas AZULES
A4: Fecha: | C4: 46100 | D4: Día: | E4: =TEXT(C4,"DDDD") | G4: Vendedora: | H4: Vilma Luna
A6: 1. CONTROL DE INVENTARIO
A7: Producto | B7: Inicio | C7: Compras | D7: Disponible | E7: Cortesías | F7: Pérdida | G7: Sobra | H7: VENDIDO | I7: Vendido $ | J7: Notas
A8: Pan Sanfran | B8: 0 | C8: 0 | D8: =B8+C8 | E8: 0 | F8: 0 | G8: 0 | H8: =D8-E8-F8-G8 | I8: —
A9: Pan Unica | B9: 0 | C9: 0 | D9: =B9+C9 | E9: 0 | F9: 0 | G9: 0 | H9: =D9-E9-F9-G9 | I9: —
A10: Salchicha Jumbo | B10: 0 | C10: 0 | D10: =B10+C10 | E10: 0 | F10: 0 | G10: 0 | H10: =D10-E10-F10-G10 | I10: —
A11: Salchicha Mini Jumbo | B11: 0 | C11: 0 | D11: =B11+C11 | E11: 0 | F11: 0 | G11: 0 | H11: =D11-E11-F11-G11 | I11: —
A12: HOTDOGS TOTAL | B12: — | C12: — | D12: — | E12: — | F12: — | G12: — | H12: =H10 | I12: — | J12: Verdad base = Salchicha Jumbo
A13: Sodas | B13: 0 | C13: 0 | D13: =B13+C13 | E13: 0 | F13: 0 | G13: 0 | H13: =D13-E13-F13-G13 | I13: =H13*PARAMETROS!B9
A14: Lays | B14: 0 | C14: 0 | D14: =B14+C14 | E14: 0 | F14: 0 | G14: 0 | H14: =D14-E14-F14-G14 | I14: =H14*PARAMETROS!B9
A15: Alitas | B15: 0 | C15: 0 | D15: =B15+C15 | E15: 0 | F15: 0 | G15: 0 | H15: =D15-E15-F15-G15 | I15: =H15*PARAMETROS!B11
A16: Chunks | B16: 0 | C16: 0 | D16: =B16+C16 | E16: 0 | F16: 0 | G16: 0 | H16: =D16-E16-F16-G16 | I16: =H16*PARAMETROS!B12
A17: Flanes | B17: 0 | C17: 0 | D17: =B17+C17 | E17: 0 | F17: 0 | G17: 0 | H17: =D17-E17-F17-G17 | I17: =H17*PARAMETROS!B10
A18: Aguas | B18: 0 | C18: 0 | D18: =B18+C18 | E18: 0 | F18: 0 | G18: 0 | H18: =D18-E18-F18-G18 | I18: —
A19: Jugos | B19: 0 | C19: 0 | D19: =B19+C19 | E19: 0 | F19: 0 | G19: 0 | H19: =D19-E19-F19-G19 | I19: —
A20: PAN vs SALCHICHA — Diferencia: | E20: =H8-H10 | F20: =IF(E20=0,"✓ CUADRA PERFECTO",IF(ABS(E20)<=2,"⚠ Diferencia marginal — revisar conteo","🚨 HALLAZGO CRÍTICO — Investigar"))
A22: 2. TICKETS REGISTRADOS
A23: Producto | B23: Cantidad | C23: Precio Unit. | D23: Subtotal | E23: Tipo | F23: HD incl. | G23: Sodas incl. | H23: Lays incl. | I23: Origen | J23: Notas
A24: Hotdog Clasico individual | B24: 0 | C24: =PARAMETROS!B1 | D24: =B24*C24 | E24: Individual | F24: 1 | G24: 0 | H24: 0 | I24: Ticket
A25: Hotdog Chilidog individual | B25: 0 | C25: =PARAMETROS!B2 | D25: =B25*C25 | E25: Individual | F25: 1 | G25: 0 | H25: 0 | I25: Ticket
A26: Hotdog Chickedog individual | B26: 0 | C26: =PARAMETROS!B3 | D26: =B26*C26 | E26: Individual | F26: 1 | G26: 0 | H26: 0 | I26: Ticket
A27: Combo Clasico | B27: 0 | C27: =PARAMETROS!B5 | D27: =B27*C27 | E27: Combo | F27: 1 | G27: 1 | H27: 1 | I27: Ticket
A28: Combo Especialidad | B28: 0 | C28: =PARAMETROS!B6 | D28: =B28*C28 | E28: Combo | F28: 1 | G28: 1 | H28: 1 | I28: Ticket
A29: Bebidas latas / Soda indiv. | B29: 0 | C29: =PARAMETROS!B7 | D29: =B29*C29 | E29: Bebida | F29: 0 | G29: 1 | H29: 0 | I29: Ticket
A30: Lays Individual | B30: 0 | C30: =PARAMETROS!B8 | D30: =B30*C30 | E30: Snack | F30: 0 | G30: 0 | H30: 1 | I30: Ticket
A31: Alitas | B31: 0 | C31: =PARAMETROS!B11 | D31: =B31*C31 | E31: Otro | F31: 0 | G31: 0 | H31: 0 | I31: Ticket
A32: Chunks | B32: 0 | C32: =PARAMETROS!B12 | D32: =B32*C32 | E32: Otro | F32: 0 | G32: 0 | H32: 0 | I32: Ticket
A33: Flanes | B33: 0 | C33: =PARAMETROS!B10 | D33: =B33*C33 | E33: Snack | F33: 0 | G33: 0 | H33: 0 | I33: Ticket
A34: TOTAL TICKET | B34: =SUM(B24:B33) | D34: =SUM(D24:D33)
A36: 3. INGRESOS Y GASTOS DEL DÍA
A37: INGRESOS | B37: Monto | D37: GASTOS | E37: Monto | F37: Categoría
A38: Corte Efectivo Total | B38: 0 | D38: Gasto 1 | E38: 0
A39: POS | B39: 0 | D39: Gasto 2 | E39: 0
A40: PedidosYa | B40: 0 | D40: Gasto 3 | E40: 0
A41: Transferencia | B41: 0 | D41: Gasto 4 | E41: 0
D42: Gasto 5 | E42: 0
D43: Gasto 6 | E43: 0
D44: Gasto 7 | E44: 0
...

Sheet BASE_DATOS
A1: SIVAR DOGS — BASE DE DATOS HISTÓRICA
A3: Fecha | B3: Día | C3: Vendedora | D3: Punto Venta | E3: Pan_Sanfran_Vendido | F3: Sal_Jumbo_Vendido | G3: Sal_MiniJumbo_Vendido | H3: Hotdogs_Total | I3: Sodas_Vendidas | J3: Lays_Vendidas | K3: T_Clasico | L3: T_Chilidog | M3: T_Chickedog | N3: T_ComboClasico | O3: T_ComboEsp | P3: T_Soda | Q3: T_Lays | R3: T_Alitas | S3: T_Chunks | T3: T_Flanes | U3: Corte_Efectivo | V3: POS | W3: PedidosYa | X3: Transferencia | Y3: Gastos_Total | Z3: Vuelto_Inicial | AA3: Vuelto_Final | AB3: Variacion_Caja | AC3: Venta_Real | AD3: Concilio_Total | AE3: Brecha | AF3: Tipo_Brecha | AG3: Semaforo | AH3: Pan_vs_Sal_Diff | AI3: Flag_Revisar | AJ3: Notas
A4: 46096 | B4: Sábado | C4: Vilma Luna | D4: Parque San Martín | E4: 229 | F4: 222 | G4: 0 | H4: 222 | I4: 84 | J4: 31 | K4: 160 | L4: 0 | M4: 0 | N4: 28 | O4: 0 | P4: 45 | Q4: 0 | R4: 1 | S4: 0 | T4: 0 | U4: 246.38 | V4: 6.5 | W4: 0 | X4: 0 | Y4: 211.27 | Z4: 24.15 | AA4: 43.35 | AB4: 19.2 | AC4: 440 | AD4: 428.75 | AE4: 11.25 | AF4: Sobrante | AG4: 🟢 Verde | AH4: 7 | AJ4: Primer cierre auditado. Pan vs Sal: error de conteo confirmado.

Sheet DASHBOARD
A1: SIVAR DOGS — DASHBOARD GERENCIAL
A2: Panel de control ejecutivo · Datos automáticos desde BASE_DATOS
A4: RESUMEN SEMANA ACTUAL
A5: Días operados | B5: Venta Total | C5: Prom. Diario | D5: Total HD Vendidos | E5: Brecha Acum. | F5: Días en Verde | G5: Días en Amarillo | H5: Días en Naranja | I5: Días en Rojo | J5: Semáforo
A6: =COUNTA(BASE_DATOS!A4:A1000)-1 | B6: =SUMIF(BASE_DATOS!A4:A1000,"<>"&"",BASE_DATOS!AB4:AB1000) | C6: =IFERROR(B6/A6,0) | D6: =SUMIF(BASE_DATOS!A4:A1000,"<>"&"",BASE_DATOS!H4:H1000) | E6: =SUMIF(BASE_DATOS!A4:A1000,"<>"&"",BASE_DATOS!AC4:AC1000) | F6: =COUNTIF(BASE_DATOS!AE4:AE1000,"🟢*") | G6: =COUNTIF(BASE_DATOS!AE4:AE1000,"🟡*") | H6: =COUNTIF(BASE_DATOS!AE4:AE1000,"🟠*") | I6: =COUNTIF(BASE_DATOS!AE4:AE1000,"🔴*") | J6: =IF(E6>=0,IF(E6<=5,"🟢 SANO",IF(E6<=10,"🟡 REVISAR",IF(E6<=15,"🟠 ALERTA","🔴 PROBLEMA"))),"🔴 FALTANTE")
A8: ÚLTIMOS DÍAS — DETALLE
A9: Fecha | B9: Día | C9: Venta Real | D9: HD Vendidos | E9: Sodas | F9: Venta Concilio | G9: Brecha | H9: Tipo | I9: Semáforo | J9: Notas
A10: =IFERROR(BASE_DATOS!A4,"") | B10: =IFERROR(BASE_DATOS!B4,"") | C10: =IFERROR(BASE_DATOS!AB4,"") | D10: =IFERROR(BASE_DATOS!H4,"") | E10: =IFERROR(BASE_DATOS!I4,"") | F10: =IFERROR(BASE_DATOS!AC4,"") | G10: =IFERROR(BASE_DATOS!AD4,"") | H10: =IFERROR(BASE_DATOS!AE4,"") | I10: =IFERROR(BASE_DATOS!AF4,"") | J10: =IFERROR(BASE_DATOS!AH4,"")
A11: =IFERROR(BASE_DATOS!A5,"") | B11: =IFERROR(BASE_DATOS!B5,"") | C11: =IFERROR(BASE_DATOS!AB5,"") | D11: =IFERROR(BASE_DATOS!H5,"") | E11: =IFERROR(BASE_DATOS!I5,"") | F11: =IFERROR(BASE_DATOS!AC5,"") | G11: =IFERROR(BASE_DATOS!AD5,"") | H11: =IFERROR(BASE_DATOS!AE5,"") | I11: =IFERROR(BASE_DATOS!AF5,"") | J11: =IFERROR(BASE_DATOS!AH5,"")
A12: =IFERROR(BASE_DATOS!A6,"") | B12: =IFERROR(BASE_DATOS!B6,"") | C12: =IFERROR(BASE_DATOS!AB6,"") | D12: =IFERROR(BASE_DATOS!H6,"") | E12: =IFERROR(BASE_DATOS!I6,"") | F12: =IFERROR(BASE_DATOS!AC6,"") | G12: =IFERROR(BASE_DATOS!AD6,"") | H12: =IFERROR(BASE_DATOS!AE6,"") | I12: =IFERROR(BASE_DATOS!AF6,"") | J12: =IFERROR(BASE_DATOS!AH6,"")
A13: =IFERROR(BASE_DATOS!A7,"") | B13: =IFERROR(BASE_DATOS!B7,"") | C13: =IFERROR(BASE_DATOS!AB7,"") | D13: =IFERROR(BASE_DATOS!H7,"") | E13: =IFERROR(BASE_DATOS!I7,"") | F13: =IFERROR(BASE_DATOS!AC7,"") | G13: =IFERROR(BASE_DATOS!AD7,"") | H13: =IFERROR(BASE_DATOS!AE7,"") | I13: =IFERROR(BASE_DATOS!AF7,"") | J13: =IFERROR(BASE_DATOS!AH7,"")
A14: =IFERROR(BASE_DATOS!A8,"") | B14: =IFERROR(BASE_DATOS!B8,"") | C14: =IFERROR(BASE_DATOS!AB8,"") | D14: =IFERROR(BASE_DATOS!H8,"") | E14: =IFERROR(BASE_DATOS!I8,"") | F14: =IFERROR(BASE_DATOS!AC8,"") | G14: =IFERROR(BASE_DATOS!AD8,"") | H14: =IFERROR(BASE_DATOS!AE8,"") | I14: =IFERROR(BASE_DATOS!AF8,"") | J14: =IFERROR(BASE_DATOS!AH8,"")
A15: =IFERROR(BASE_DATOS!A9,"") | B15: =IFERROR(BASE_DATOS!B9,"") | C15: =IFERROR(BASE_DATOS!AB9,"") | D15: =IFERROR(BASE_DATOS!H9,"") | E15: =IFERROR(BASE_DATOS!I9,"") | F15: =IFERROR(BASE_DATOS!AC9,"") | G15: =IFERROR(BASE_DATOS!AD9,"") | H15: =IFERROR(BASE_DATOS!AE9,"") | I15: =IFERROR(BASE_DATOS!AF9,"") | J15: =IFERROR(BASE_DATOS!AH9,"")
A16: =IFERROR(BASE_DATOS!A10,"") | B16: =IFERROR(BASE_DATOS!B10,"") | C16: =IFERROR(BASE_DATOS!AB10,"") | D16: =IFERROR(BASE_DATOS!H10,"") | E16: =IFERROR(BASE_DATOS!I10,"") | F16: =IFERROR(BASE_DATOS!AC10,"") | G16: =IFERROR(BASE_DATOS!AD10,"") | H16: =IFERROR(BASE_DATOS!AE10,"") | I16: =IFERROR(BASE_DATOS!AF10,"") | J16: =IFERROR(BASE_DATOS!AH10,"")
A17: =IFERROR(BASE_DATOS!A11,"") | B17: =IFERROR(BASE_DATOS!B11,"") | C17: =IFERROR(BASE_DATOS!AB11,"") | D17: =IFERROR(BASE_DATOS!H11,"") | E17: =IFERROR(BASE_DATOS!I11,"") | F17: =IFERROR(BASE_DATOS!AC11,"") | G17: =IFERROR(BASE_DATOS!AD11,"") | H17: =IFERROR(BASE_DATOS!AE11,"") | I17: =IFERROR(BASE_DATOS!AF11,"") | J17: =IFERROR(BASE_DATOS!AH11,"")
A18: =IFERROR(BASE_DATOS!A12,"") | B18: =IFERROR(BASE_DATOS!B12,"") | C18: =IFERROR(BASE_DATOS!AB12,"") | D18: =IFERROR(BASE_DATOS!H12,"") | E18: =IFERROR(BASE_DATOS!I12,"") | F18: =IFERROR(BASE_DATOS!AC12,"") | G18: =IFERROR(BASE_DATOS!AD12,"") | H18: =IFERROR(BASE_DATOS!AE12,"") | I18: =IFERROR(BASE_DATOS!AF12,"") | J18: =IFERROR(BASE_DATOS!AH12,"")
A19: =IFERROR(BASE_DATOS!A13,"") | B19: =IFERROR(BASE_DATOS!B13,"") | C19: =IFERROR(BASE_DATOS!AB13,"") | D19: =IFERROR(BASE_DATOS!H13,"") | E19: =IFERROR(BASE_DATOS!I13,"") | F19: =IFERROR(BASE_DATOS!AC13,"") | G19: =IFERROR(BASE_DATOS!AD13,"") | H19: =IFERROR(BASE_DATOS!AE13,"") | I19: =IFERROR(BASE_DATOS!AF13,"") | J19: =IFERROR(BASE_DATOS!AH13,"")
